Workbook
Name Slicer_industry: #N/A

Sheet company_info
A1: company_id | B1: company_name | C1: industry | D1: region
A2: 1 | B2: Company_1 | C2: Retail | D2: Latin America
A3: 2 | B3: Company_2 | C3: Retail | D3: Asia
A4: 3 | B4: Company_3 | C4: Transportation | D4: Latin America
A5: 4 | B5: Company_4 | C5: Technology | D5: Africa
A6: 5 | B6: Company_5 | C6: Finance | D6: Middle East
A7: 6 | B7: Company_6 | C7: Transportation | D7: Oceania
A8: 7 | B8: Company_7 | C8: Healthcare | D8: Oceania
A9: 8 | B9: Company_8 | C9: Healthcare | D9: Europe
A10: 9 | B10: Company_9 | C10: Technology | D10: North America
A11: 10 | B11: Company_10 | C11: Technology | D11: Latin America
A12: 11 | B12: Company_11 | C12: Energy | D12: Europe
A13: 12 | B13: Company_12 | C13: Finance | D13: Asia
... A1001: 1000 | B1001: Company_1000 | C1001: Consumer Goods | D1001: Latin America

Sheet PivotTable
A1: Lab In-Class | T1: Lab Assignments
A3: Row Labels | B3: Sum of revenue | T3: Task 1 : Create a PivotTable to analyze the total carbon emissions by industry and region. Identify which industry–region combination has the highest total carbon emissions.
A4: Consumer Goods | B4: 2678226.1
A5: Energy | B5: 10453492
A6: Finance | B6: 7798538
A7: Healthcare | B7: 6194071.5
A8: Manufacturing | B8: 2977921.4 | T8: Sum of carbon_emissions | U8: Column Labels
A9: Retail | B9: 1881065.6 | T9: Row Labels | U9: Consumer Goods | V9: Energy | W9: Finance | X9: Healthcare | Y9: Manufacturing | Z9: Retail | AA9: Technology | AB9: Transportation | AC9: Utilities | AD9: Grand Total
A10: Technology | B10: 16482469 | T10: Africa | U10: 42847365 | V10: 1.1780521e+09 | W10: 13151770 | X10: 45709293 | Y10: 80940682 | Z10: 14984708 | AA10: 51999506 | AB10: 81298609 | AC10: 1.5136328e+08 | AD10: 1.6603473e+09
A11: Transportation | B11: 1449137.7 | T11: Asia | U11: 59109464 | V11: 1.2111835e+09 | W11: 17194593 | X11: 47356765 | Y11: 1.5466309e+08 | Z11: 16206975 | AA11: 56986861 | AB11: 1.9618781e+08 | AC11: 1.1351593e+08 | AD11: 1.872405e+09
A12: Utilities | B12: 1464435.4 | T12: Europe | U12: 56145702 | V12: 1.8055009e+09 | W12: 10806173 | X12: 95756867 | Y12: 61260046 | Z12: 22479401 | AA12: 77024875 | AB12: 69242905 | AC12: 1.9304964e+08 | AD12: 2.3912665e+09
A13: Grand Total | B13: 51379356 | T13: Latin America | U13: 57698652 | V13: 1.1241623e+09 | W13: 15111642 | X13: 61971463 | Y13: 84728820 | Z13: 24017203 | AA13: 1.1092493e+08 | AB13: 1.1758544e+08 | AC13: 1.1002278e+08 | AD13: 1.7062233e+09
T14: Middle East | U14: 48382200 | V14: 8.0439529e+08 | W14: 15327691 | X14: 52578431 | Y14: 1.5806595e+08 | Z14: 32925941 | AA14: 57693206 | AB14: 1.3465692e+08 | AC14: 1.3117792e+08 | AD14: 1.4352035e+09
T15: North America | U15: 67229439 | V15: 1.7673207e+09 | W15: 8439771 | X15: 53490062 | Y15: 1.5602664e+08 | Z15: 22340150 | AA15: 70538684 | AB15: 1.1451314e+08 | AC15: 1.0984507e+08 | AD15: 2.3697436e+09
T16: Oceania | U16: 1.0289732e+08 | V16: 1.8406077e+09 | W16: 9527074.2 | X16: 89460265 | Y16: 1.0688393e+08 | Z16: 18290500 | AA16: 45519511 | AB16: 1.2347048e+08 | AC16: 2.1423984e+08 | AD16: 2.5508966e+09
A17: Sum of revenue | B17: Column Labels | T17: Grand Total | U17: 4.3431014e+08 | V17: 9.7312225e+09 | W17: 89558714 | X17: 4.4632315e+08 | Y17: 8.0256914e+08 | Z17: 1.5124488e+08 | AA17: 4.7068757e+08 | AB17: 836955297 | AC17: 1.0232145e+09 | AD17: 1.3986086e+10
A18: Row Labels | B18: Africa | C18: Asia | D18: Europe | E18: Latin America | F18: Middle East | G18: North America | H18: Oceania | I18: Grand Total
A19: Consumer Goods | B19: 246636.8 | C19: 338709.4 | D19: 378146.5 | E19: 362525.8 | F19: 292105.6 | G19: 409262.5 | H19: 650839.5 | I19: 2678226.1
A20: Energy | B20: 1331500.5 | C20: 1334846.2 | D20: 2119352.8 | E20: 1237418.3 | F20: 858027 | G20: 1715777.3 | H20: 1856569.7 | I20: 10453492 | T20: Answer : Energy Industry in Oceania has most carbon emissions
A21: Finance | B21: 1125943.4 | C21: 1495207 | D21: 948469.6 | E21: 1298388.5 | F21: 1392568 | G21: 710769.9 | H21: 827191.6 | I21: 7798538
A22: Healthcare | B22: 587551.7 | C22: 649012.1 | D22: 1423773 | E22: 892830.8 | F22: 706949.7 | G22: 731240.6 | H22: 1202713.6 | I22: 6194071.5
A23: Manufacturing | B23: 300643.8 | C23: 591558 | D23: 216667.8 | E23: 304327.3 | F23: 612105.2 | G23: 543127.7 | H23: 409491.6 | I23: 2977921.4
A24: Retail | B24: 197206.6 | C24: 208750.9 | D24: 271109.5 | E24: 289924 | F24: 435022.8 | G24: 259543.8 | H24: 219508 | I24: 1881065.6
A25: Technology | B25: 1788148.3 | C25: 1884813 | D25: 2877799.5 | E25: 3791662.3 | F25: 2032004 | G25: 2491201.8 | H25: 1616840.1 | I25: 16482469
A26: Transportation | B26: 142370.9 | C26: 321790.3 | D26: 129527.4 | E26: 198424.2 | F26: 228439 | G26: 209874.6 | H26: 218711.3 | I26: 1449137.7
A27: Utilities | B27: 221250.7 | C27: 168624.8 | D27: 251237.8 | E27: 164120.9 | F27: 196736.5 | G27: 158115.2 | H27: 304349.5 | I27: 1464435.4
A28: Grand Total | B28: 5941252.7 | C28: 6993311.7 | D28: 8616083.9 | E28: 8539622.1 | F28: 6753957.8 | G28: 7228913.4 | H28: 7306214.9 | I28: 51379356 | T28: Task 2 : Create a PivotTable to analyze the average water usage by industry and year. Use a filter to analyze a specific region. Which industry has the highest average water usage in the selected region (Asia)?
A32: Row Labels | B32: Average of esg_environmental | T32: region | U32: (All)
A33: Consumer Goods | B33: 52.079389
A34: Energy | B34: 39.663468 | T34: Average of water_usage | U34: Column Labels
A35: Finance | B35: 90.252856 | T35: Row Labels | U35: Consumer Goods | V35: Energy | W35: Finance | X35: Healthcare | Y35: Manufacturing | Z35: Retail | AA35: Technology | AB35: Transportation | AC35: Utilities | AD35: Grand Total
A36: Healthcare | B36: 66.228926 | T36: 2015 | U36: 342177.99 | V36: 1888819.6 | W36: 28540.21 | X36: 230098.3 | Y36: 678932.38 | Z36: 50603.035 | AA36: 177753.43 | AB36: 86411.103 | AC36: 508612.87 | AD36: 440969.37
A37: Manufacturing | B37: 41.499301 | T37: 2016 | U37: 356717.7 | V37: 1907837.9 | W37: 29725.071 | X37: 247895.29 | Y37: 706440.98 | Z37: 53056.295 | AA37: 190655.61 | AB37: 89775.862 | AC37: 506833.2 | AD37: 451904.78
A38: Retail | B38: 57.697427 | T38: 2017 | U38: 373583.56 | V38: 2013259.6 | W38: 31212.725 | X38: 262605.49 | Y38: 720560.59 | Z38: 55730.908 | AA38: 206478.58 | AB38: 91820.418 | AC38: 512588.5 | AD38: 471488.52
A39: Technology | B39: 84.289761 | T39: 2018 | U39: 386657.69 | V39: 2103466.3 | W39: 32580.552 | X39: 279050.37 | Y39: 751732.68 | Z39: 57655.234 | AA39: 221555.45 | AB39: 96058.995 | AC39: 523373.16 | AD39: 491825.12
A40: Transportation | B40: 33.847242 | T40: 2019 | U40: 400619.3 | V40: 2211022.1 | W40: 33909.889 | X40: 301576.43 | Y40: 786870.01 | Z40: 60523.975 | AA40: 241397.64 | AB40: 99720.803 | AC40: 537732.28 | AD40: 516201.59
A41: Utilities | B41: 46.176211 | T41: 2020 | U41: 417529.9 | V41: 2305484 | W41: 36279.472 | X41: 327081.1 | Y41: 819920.19 | Z41: 63115.945 | AA41: 257320.79 | AB41: 104256.16 | AC41: 542819.24 | AD41: 538448.19
A42: Grand Total | B42: 56.416991 | T42: 2021 | U42: 432662.28 | V42: 2429714.8 | W42: 37934.615 | X42: 346225.11 | Y42: 856823.55 | Z42: 65565.659 | AA42: 282796.78 | AB42: 109971.82 | AC42: 553428.92 | AD42: 564925.48
T43: 2022 | U43: 452483.29 | V43: 2621853.9 | W43: 39047.626 | X43: 369516.33 | Y43: 888123.22 | Z43: 70173.509 | AA43: 305876.01 | AB43: 116918.07 | AC43: 562938.3 | AD43: 599092.98
T44: 2023 | U44: 476678.19 | V44: 2857950.6 | W44: 40388.465 | X44: 404808.97 | Y44: 937107.33 | Z44: 74185.267 | AA44: 334371.75 | AB44: 124596.46 | AC44: 569069.21 | AD44: 642237.82
...

Sheet company_perf
A1: performance_id | B1: company_id | C1: company_name | D1: industry | E1: region | F1: year | G1: revenue | H1: profit_margin | I1: market_cap | J1: growth_rate | K1: esg_overall | L1: esg_environmental | M1: esg_social | N1: esg_governance | O1: carbon_emissions | P1: water_usage | Q1: energy_consumption
A2: 1 | B2: 1 | C2: =_xlfn.XLOOKUP(company_perf[[#This Row],[company_id]],'company_info'!A:A,'company_info'!B:B) -> Company_1 | D2: =VLOOKUP(company_perf[[#This Row],[company_id]],company_info[],3,FALSE) -> Retail | E2: =VLOOKUP(company_perf[[#This Row],[company_id]],company_info[],4,FALSE) -> Latin America | F2: 2015 | G2: 459.2 | H2: 6 | I2: 337.5 | K2: 57 | L2: 60.7 | M2: 33.5 | N2: 76.8 | O2: 35577.4 | P2: 17788.7 | Q2: 71154.7
A3: 2 | B3: 1 | C3: =_xlfn.XLOOKUP(company_perf[[#This Row],[company_id]],'company_info'!A:A,'company_info'!B:B) -> Company_1 | D3: =VLOOKUP(company_perf[[#This Row],[company_id]],company_info[],3,FALSE) -> Retail | E3: =VLOOKUP(company_perf[[#This Row],[company_id]],company_info[],4,FALSE) -> Latin America | F3: 2016 | G3: 473.8 | H3: 4.6 | I3: 366.6 | J3: 3.2 | K3: 56.7 | L3: 58.9 | M3: 32.8 | N3: 78.5 | O3: 37314.7 | P3: 18657.4 | Q3: 74629.4
A4: 3 | B4: 1 | C4: =_xlfn.XLOOKUP(company_perf[[#This Row],[company_id]],'company_info'!A:A,'company_info'!B:B) -> Company_1 | D4: =VLOOKUP(company_perf[[#This Row],[company_id]],company_info[],3,FALSE) -> Retail | E4: =VLOOKUP(company_perf[[#This Row],[company_id]],company_info[],4,FALSE) -> Latin America | F4: 2017 | G4: 564.9 | H4: 5.2 | I4: 313.4 | J4: 19.2 | K4: 56.5 | L4: 57.6 | M4: 34 | N4: 77.8 | O4: 45006.4 | P4: 22503.2 | Q4: 90012.9
A5: 4 | B5: 1 | C5: =_xlfn.XLOOKUP(company_perf[[#This Row],[company_id]],'company_info'!A:A,'company_info'!B:B) -> Company_1 | D5: =VLOOKUP(company_perf[[#This Row],[company_id]],company_info[],3,FALSE) -> Retail | E5: =VLOOKUP(company_perf[[#This Row],[company_id]],company_info[],4,FALSE) -> Latin America | F5: 2018 | G5: 558.4 | H5: 4.3 | I5: 283 | J5: -1.1 | K5: 58 | L5: 62.3 | M5: 33.4 | N5: 78.3 | O5: 42650.1 | P5: 21325.1 | Q5: 85300.2
A6: 5 | B6: 1 | C6: =_xlfn.XLOOKUP(company_perf[[#This Row],[company_id]],'company_info'!A:A,'company_info'!B:B) -> Company_1 | D6: =VLOOKUP(company_perf[[#This Row],[company_id]],company_info[],3,FALSE) -> Retail | E6: =VLOOKUP(company_perf[[#This Row],[company_id]],company_info[],4,FALSE) -> Latin America | F6: 2019 | G6: 554.5 | H6: 4.9 | I6: 538.1 | J6: -0.7 | K6: 56.6 | L6: 63.7 | M6: 30 | N6: 76.1 | O6: 41799.4 | P6: 20899.7 | Q6: 83598.8
A7: 6 | B7: 1 | C7: =_xlfn.XLOOKUP(company_perf[[#This Row],[company_id]],'company_info'!A:A,'company_info'!B:B) -> Company_1 | D7: =VLOOKUP(company_perf[[#This Row],[company_id]],company_info[],3,FALSE) -> Retail | E7: =VLOOKUP(company_perf[[#This Row],[company_id]],company_info[],4,FALSE) -> Latin America | F7: 2020 | G7: 567.5 | H7: 6 | I7: 384.1 | J7: 2.3 | K7: 55.7 | L7: 65.1 | M7: 28.5 | N7: 73.5 | O7: 42245.4 | P7: 21122.7 | Q7: 84490.9
A8: 7 | B8: 1 | C8: =_xlfn.XLOOKUP(company_perf[[#This Row],[company_id]],'company_info'!A:A,'company_info'!B:B) -> Company_1 | D8: =VLOOKUP(company_perf[[#This Row],[company_id]],company_info[],3,FALSE) -> Retail | E8: =VLOOKUP(company_perf[[#This Row],[company_id]],company_info[],4,FALSE) -> Latin America | F8: 2021 | G8: 604.2 | H8: 5.2 | I8: 479.3 | J8: 6.5 | K8: 55.6 | L8: 66.8 | M8: 25.5 | N8: 74.6 | O8: 44263.8 | P8: 22131.9 | Q8: 88527.7
A9: 8 | B9: 1 | C9: =_xlfn.XLOOKUP(company_perf[[#This Row],[company_id]],'company_info'!A:A,'company_info'!B:B) -> Company_1 | D9: =VLOOKUP(company_perf[[#This Row],[company_id]],company_info[],3,FALSE) -> Retail | E9: =VLOOKUP(company_perf[[#This Row],[company_id]],company_info[],4,FALSE) -> Latin America | F9: 2022 | G9: 593.2 | H9: 4.2 | I9: 248.4 | J9: -1.8 | K9: 57.7 | L9: 69 | M9: 27.1 | N9: 76.9 | O9: 42536.3 | P9: 21268.2 | Q9: 85072.6
A10: 9 | B10: 1 | C10: =_xlfn.XLOOKUP(company_perf[[#This Row],[company_id]],'company_info'!A:A,'company_info'!B:B) -> Company_1 | D10: =VLOOKUP(company_perf[[#This Row],[company_id]],company_info[],3,FALSE) -> Retail | E10: =VLOOKUP(company_perf[[#This Row],[company_id]],company_info[],4,FALSE) -> Latin America | F10: 2023 | G10: 636.7 | H10: 5.3 | I10: 373.9 | J10: 7.3 | K10: 57.8 | L10: 68.3 | M10: 27 | N10: 78.1 | O10: 45956.3 | P10: 22978.2 | Q10: 91912.6
A11: 10 | B11: 1 | C11: =_xlfn.XLOOKUP(company_perf[[#This Row],[company_id]],'company_info'!A:A,'company_info'!B:B) -> Company_1 | D11: =VLOOKUP(company_perf[[#This Row],[company_id]],company_info[],3,FALSE) -> Retail | E11: =VLOOKUP(company_perf[[#This Row],[company_id]],company_info[],4,FALSE) -> Latin America | F11: 2024 | G11: 687 | H11: 4.6 | I11: 460.1 | J11: 7.9 | K11: 58.5 | L11: 68.9 | M11: 29.9 | N11: 76.8 | O11: 49289.1 | P11: 24644.5 | Q11: 98578.1
A12: 11 | B12: 1 | C12: =_xlfn.XLOOKUP(company_perf[[#This Row],[company_id]],'company_info'!A:A,'company_info'!B:B) -> Company_1 | D12: =VLOOKUP(company_perf[[#This Row],[company_id]],company_info[],3,FALSE) -> Retail | E12: =VLOOKUP(company_perf[[#This Row],[company_id]],company_info[],4,FALSE) -> Latin America | F12: 2025 | G12: 734.5 | H12: 5 | I12: 628.8 | J12: 6.9 | K12: 59.2 | L12: 70.7 | M12: 29.1 | N12: 78 | O12: 51805.8 | P12: 25902.9 | Q12: 103611.7
A13: 12 | B13: 2 | C13: =_xlfn.XLOOKUP(company_perf[[#This Row],[company_id]],'company_info'!A:A,'company_info'!B:B) -> Company_2 | D13: =VLOOKUP(company_perf[[#This Row],[company_id]],company_info[],3,FALSE) -> Retail | E13: =VLOOKUP(company_perf[[#This Row],[company_id]],company_info[],4,FALSE) -> Asia | F13: 2015 | G13: 2934.8 | H13: -2.9 | I13: 1803.1 | K13: 59.9 | L13: 61.1 | M13: 48.6 | N13: 69.8 | O13: 226554.2 | P13: 113277.1 | Q13: 453108.3
A14: 13 | B14: 2 | C14: =_xlfn.XLOOKUP(company_perf[[#This Row],[company_id]],'company_info'!A:A,'company_info'!B:B) -> Company_2 | D14: =VLOOKUP(company_perf[[#This Row],[company_id]],company_info[],3,FALSE) -> Retail | E14: =VLOOKUP(company_perf[[#This Row],[company_id]],company_info[],4,FALSE) -> Asia | F14: 2016 | G14: 3140.3 | H14: -1.1 | I14: 13885.2 | J14: 7 | K14: 60.6 | L14: 61.1 | M14: 50.1 | N14: 70.5 | O14: 242555.1 | P14: 121277.6 | Q14: 485110.3
A15: 14 | B15: 2 | C15: =_xlfn.XLOOKUP(company_perf[[#This Row],[company_id]],'company_info'!A:A,'company_info'!B:B) -> Company_2 | D15: =VLOOKUP(company_perf[[#This Row],[company_id]],company_info[],3,FALSE) -> Retail | E15: =VLOOKUP(company_perf[[#This Row],[company_id]],company_info[],4,FALSE) -> Asia | F15: 2017 | G15: 3463.1 | H15: -2.2 | I15: 5283.7 | J15: 10.3 | K15: 61.7 | L15: 61.4 | M15: 53.1 | N15: 70.5 | O15: 266651.3 | P15: 133325.7 | Q15: 533302.7
A16: 15 | B16: 2 | C16: =_xlfn.XLOOKUP(company_perf[[#This Row],[company_id]],'company_info'!A:A,'company_info'!B:B) -> Company_2 | D16: =VLOOKUP(company_perf[[#This Row],[company_id]],company_info[],3,FALSE) -> Retail | E16: =VLOOKUP(company_perf[[#This Row],[company_id]],company_info[],4,FALSE) -> Asia | F16: 2018 | G16: 2939.7 | H16: -1.7 | I16: 4408 | J16: -15.1 | K16: 61.5 | L16: 61.7 | M16: 52 | N16: 70.6 | O16: 225701.3 | P16: 112850.6 | Q16: 451402.6
A17: 16 | B17: 2 | C17: =_xlfn.XLOOKUP(company_perf[[#This Row],[company_id]],'company_info'!A:A,'company_info'!B:B) -> Company_2 | D17: =VLOOKUP(company_perf[[#This Row],[company_id]],company_info[],3,FALSE) -> Retail | E17: =VLOOKUP(company_perf[[#This Row],[company_id]],company_info[],4,FALSE) -> Asia | F17: 2019 | G17: 3125.6 | H17: 1.2 | I17: 566.4 | J17: 6.3 | K17: 61.1 | L17: 63.1 | M17: 52.5 | N17: 67.8 | O17: 237019.5 | P17: 118509.7 | Q17: 474039
A18: 17 | B18: 2 | C18: =_xlfn.XLOOKUP(company_perf[[#This Row],[company_id]],'company_info'!A:A,'company_info'!B:B) -> Company_2 | D18: =VLOOKUP(company_perf[[#This Row],[company_id]],company_info[],3,FALSE) -> Retail | E18: =VLOOKUP(company_perf[[#This Row],[company_id]],company_info[],4,FALSE) -> Asia | F18: 2020 | G18: 2999.8 | H18: -0.3 | I18: 1997.8 | J18: -4 | K18: 63.3 | L18: 64.2 | M18: 57.9 | N18: 67.9 | O18: 225128.2 | P18: 112564.1 | Q18: 450256.4
A19: 18 | B19: 2 | C19: =_xlfn.XLOOKUP(company_perf[[#This Row],[company_id]],'company_info'!A:A,'company_info'!B:B) -> Company_2 | D19: =VLOOKUP(company_perf[[#This Row],[company_id]],company_info[],3,FALSE) -> Retail | E19: =VLOOKUP(company_perf[[#This Row],[company_id]],company_info[],4,FALSE) -> Asia | F19: 2021 | G19: 3167.9 | H19: -0.4 | I19: 15634.9 | J19: 5.6 | K19: 63 | L19: 62.9 | M19: 60 | N19: 66.1 | O19: 240710.6 | P19: 120355.3 | Q19: 481421.2
A20: 19 | B20: 2 | C20: =_xlfn.XLOOKUP(company_perf[[#This Row],[company_id]],'company_info'!A:A,'company_info'!B:B) -> Company_2 | D20: =VLOOKUP(company_perf[[#This Row],[company_id]],company_info[],3,FALSE) -> Retail | E20: =VLOOKUP(company_perf[[#This Row],[company_id]],company_info[],4,FALSE) -> Asia | F20: 2022 | G20: 3106.4 | H20: 0.8 | I20: 514.3 | J20: -1.9 | K20: 64 | L20: 66.7 | M20: 57.7 | N20: 67.8 | O20: 227761.4 | P20: 113880.7 | Q20: 455522.7
A21: 20 | B21: 2 | C21: =_xlfn.XLOOKUP(company_perf[[#This Row],[company_id]],'company_info'!A:A,'company_info'!B:B) -> Company_2 | D21: =VLOOKUP(company_perf[[#This Row],[company_id]],company_info[],3,FALSE) -> Retail | E21: =VLOOKUP(company_perf[[#This Row],[company_id]],company_info[],4,FALSE) -> Asia | F21: 2023 | G21: 3691.6 | H21: -0.7 | I21: 2523.2 | J21: 18.8 | K21: 66 | L21: 66.6 | M21: 61.6 | N21: 70 | O21: 271015.1 | P21: 135507.6 | Q21: 542030.3
A22: 21 | B22: 2 | C22: =_xlfn.XLOOKUP(company_perf[[#This Row],[company_id]],'company_info'!A:A,'company_info'!B:B) -> Company_2 | D22: =VLOOKUP(company_perf[[#This Row],[company_id]],company_info[],3,FALSE) -> Retail | E22: =VLOOKUP(company_perf[[#This Row],[company_id]],company_info[],4,FALSE) -> Asia | F22: 2024 | G22: 3822.9 | H22: -1.2 | I22: 5807.8 | J22: 3.6 | K22: 65.7 | L22: 65.4 | M22: 63 | N22: 68.7 | O22: 283660 | P22: 141830 | Q22: 567320
A23: 22 | B23: 2 | C23: =_xlfn.XLOOKUP(company_perf[[#This Row],[company_id]],'company_info'!A:A,'company_info'!B:B) -> Company_2 | D23: =VLOOKUP(company_perf[[#This Row],[company_id]],company_info[],3,FALSE) -> Retail | E23: =VLOOKUP(company_perf[[#This Row],[company_id]],company_info[],4,FALSE) -> Asia | F23: 2025 | G23: 4371.5 | H23: -2.4 | I23: 20376.3 | J23: 14.4 | K23: 66.3 | L23: 65.8 | M23: 62.8 | N23: 70.3 | O23: 323282 | P23: 161641 | Q23: 646564.1
A24: 23 | B24: 3 | C24: =_xlfn.XLOOKUP(company_perf[[#This Row],[company_id]],'company_info'!A:A,'company_info'!B:B) -> Company_3 | D24: =VLOOKUP(company_perf[[#This Row],[company_id]],company_info[],3,FALSE) -> Transportation | E24: =VLOOKUP(company_perf[[#This Row],[company_id]],company_info[],4,FALSE) -> Latin America | F24: 2015 | G24: 259.7 | H24: 5.9 | I24: 140.2 | K24: 25.5 | L24: 3.3 | M24: 41.6 | N24: 31.5 | O24: 183314.5 | P24: 30552.4 | Q24: 611048.2
A25: 24 | B25: 3 | C25: =_xlfn.XLOOKUP(company_perf[[#This Row],[company_id]],'company_info'!A:A,'company_info'!B:B) -> Company_3 | D25: =VLOOKUP(company_perf[[#This Row],[company_id]],company_info[],3,FALSE) -> Transportation | E25: =VLOOKUP(company_perf[[#This Row],[company_id]],company_info[],4,FALSE) -> Latin America | F25: 2016 | G25: 245.2 | H25: 8.5 | I25: 224 | J25: -5.6 | K25: 26.9 | L25: 7 | M25: 40.2 | N25: 33.5 | O25: 169346.3 | P25: 28224.4 | Q25: 564487.8
A26: 25 | B26: 3 | C26: =_xlfn.XLOOKUP(company_perf[[#This Row],[company_id]],'company_info'!A:A,'company_info'!B:B) -> Company_3 | D26: =VLOOKUP(company_perf[[#This Row],[company_id]],company_info[],3,FALSE) -> Transportation | E26: =VLOOKUP(company_perf[[#This Row],[company_id]],company_info[],4,FALSE) -> Latin America | F26: 2017 | G26: 282.4 | H26: 6.5 | I26: 289.7 | J26: 15.2 | K26: 27.9 | L26: 8.8 | M26: 42.6 | N26: 32.3 | O26: 192824.3 | P26: 32137.4 | Q26: 642747.8
A27: 26 | B27: 3 | C27: =_xlfn.XLOOKUP(company_perf[[#This Row],[company_id]],'company_info'!A:A,'company_info'!B:B) -> Company_3 | D27: =VLOOKUP(company_perf[[#This Row],[company_id]],company_info[],3,FALSE) -> Transportation | E27: =VLOOKUP(company_perf[[#This Row],[company_id]],company_info[],4,FALSE) -> Latin America | F27: 2018 | G27: 300.2 | H27: 3.1 | I27: 100.7 | J27: 6.3 | K27: 28.2 | L27: 8.3 | M27: 42.9 | N27: 33.5 | O27: 205699.6 | P27: 34283.3 | Q27: 685665.5
A28: 27 | B28: 3 | C28: =_xlfn.XLOOKUP(company_perf[[#This Row],[company_id]],'company_info'!A:A,'company_info'!B:B) -> Company_3 | D28: =VLOOKUP(company_perf[[#This Row],[company_id]],company_info[],3,FALSE) -> Transportation | E28: =VLOOKUP(company_perf[[#This Row],[company_id]],company_info[],4,FALSE) -> Latin America | F28: 2019 | G28: 322.6 | H28: 5.1 | I28: 290.7 | J28: 7.5 | K28: 29.8 | L28: 14.8 | M28: 43.6 | N28: 31.2 | O28: 212286.3 | P28: 35381 | Q28: 707621
A29: 28 | B29: 3 | C29: =_xlfn.XLOOKUP(company_perf[[#This Row],[company_id]],'company_info'!A:A,'company_info'!B:B) -> Company_3 | D29: =VLOOKUP(company_perf[[#This Row],[company_id]],company_info[],3,FALSE) -> Transportation | E29: =VLOOKUP(company_perf[[#This Row],[company_id]],company_info[],4,FALSE) -> Latin America | F29: 2020 | G29: 337.9 | H29: 2.7 | I29: 76.5 | J29: 4.7 | K29: 30.8 | L29: 17.7 | M29: 42 | N29: 32.6 | O29: 218171.7 | P29: 36362 | Q29: 727239
A30: 29 | B30: 3 | C30: =_xlfn.XLOOKUP(company_perf[[#This Row],[company_id]],'company_info'!A:A,'company_info'!B:B) -> Company_3 | D30: =VLOOKUP(company_perf[[#This Row],[company_id]],company_info[],3,FALSE) -> Transportation | E30: =VLOOKUP(company_perf[[#This Row],[company_id]],company_info[],4,FALSE) -> Latin America | F30: 2021 | G30: 348.4 | H30: 4.5 | I30: 128.8 | J30: 3.1 | K30: 31.6 | L30: 18.5 | M30: 43.9 | N30: 32.2 | O30: 223833 | P30: 37305.5 | Q30: 746110
A31: 30 | B31: 3 | C31: =_xlfn.XLOOKUP(company_perf[[#This Row],[company_id]],'company_info'!A:A,'company_info'!B:B) -> Company_3 | D31: =VLOOKUP(company_perf[[#This Row],[company_id]],company_info[],3,FALSE) -> Transportation | E31: =VLOOKUP(company_perf[[#This Row],[company_id]],company_info[],4,FALSE) -> Latin America | F31: 2022 | G31: 389.6 | H31: 7.1 | I31: 327.9 | J31: 11.8 | K31: 31.3 | L31: 18.8 | M31: 44.9 | N31: 30.2 | O31: 249794.5 | P31: 41632.4 | Q31: 832648.3
A32: 31 | B32: 3 | C32: =_xlfn.XLOOKUP(company_perf[[#This Row],[company_id]],'company_info'!A:A,'company_info'!B:B) -> Company_3 | D32: =VLOOKUP(company_perf[[#This Row],[company_id]],company_info[],3,FALSE) -> Transportation | E32: =VLOOKUP(company_perf[[#This Row],[company_id]],company_info[],4,FALSE) -> Latin America | F32: 2023 | G32: 415.2 | H32: 8.1 | I32: 498.7 | J32: 6.6 | K32: 32.3 | L32: 20.2 | M32: 43.8 | N32: 32.9 | O32: 263632.1 | P32: 43938.7 | Q32: 878773.7
A33: 32 | B33: 3 | C33: =_xlfn.XLOOKUP(company_perf[[#This Row],[company_id]],'company_info'!A:A,'company_info'!B:B) -> Company_3 | D33: =VLOOKUP(company_perf[[#This Row],[company_id]],company_info[],3,FALSE) -> Transportation | E33: =VLOOKUP(company_perf[[#This Row],[company_id]],company_info[],4,FALSE) -> Latin America | F33: 2024 | G33: 438 | H33: 10.3 | I33: 739.4 | J33: 5.5 | K33: 32.1 | L33: 23.4 | M33: 41.5 | N33: 31.5 | O33: 272361.8 | P33: 45393.6 | Q33: 907872.8
A34: 33 | B34: 3 | C34: =_xlfn.XLOOKUP(company_perf[[#This Row],[company_id]],'company_info'!A:A,'company_info'!B:B) -> Company_3 | D34: =VLOOKUP(company_perf[[#This Row],[company_id]],company_info[],3,FALSE) -> Transportation | E34: =VLOOKUP(company_perf[[#This Row],[company_id]],company_info[],4,FALSE) -> Latin America | F34: 2025 | G34: 479.8 | H34: 11.6 | I34: 1020.7 | J34: 9.5 | K34: 34.3 | L34: 24.4 | M34: 43.7 | N34: 34.9 | O34: 296242 | P34: 49373.7 | Q34: 987473.3
A35: 34 | B35: 4 | C35: =_xlfn.XLOOKUP(company_perf[[#This Row],[company_id]],'company_info'!A:A,'company_info'!B:B) -> Company_4 | D35: =VLOOKUP(company_perf[[#This Row],[company_id]],company_info[],3,FALSE) -> Technology | E35: =VLOOKUP(company_perf[[#This Row],[company_id]],company_info[],4,FALSE) -> Africa | F35: 2015 | G35: 5036.7 | H35: 21.2 | I35: 23192.4 | K35: 54.2 | L35: 97.6 | M35: 46.2 | N35: 18.9 | O35: 130146.6 | P35: 78087.9 | Q35: 260293.2
A36: 35 | B36: 4 | C36: =_xlfn.XLOOKUP(company_perf[[#This Row],[company_id]],'company_info'!A:A,'company_info'!B:B) -> Company_4 | D36: =VLOOKUP(company_perf[[#This Row],[company_id]],company_info[],3,FALSE) -> Technology | E36: =VLOOKUP(company_perf[[#This Row],[company_id]],company_info[],4,FALSE) -> Africa | F36: 2016 | G36: 5192.5 | H36: 25.1 | I36: 25137.8 | J36: 3.1 | K36: 54.6 | L36: 98.9 | M36: 45.2 | N36: 19.9 | O36: 131888.8 | P36: 79133.3 | Q36: 263777.6
A37: 36 | B37: 4 | C37: =_xlfn.XLOOKUP(company_perf[[#This Row],[company_id]],'company_info'!A:A,'company_info'!B:B) -> Company_4 | D37: =VLOOKUP(company_perf[[#This Row],[company_id]],company_info[],3,FALSE) -> Technology | E37: =VLOOKUP(company_perf[[#This Row],[company_id]],company_info[],4,FALSE) -> Africa | F37: 2017 | G37: 5497.1 | H37: 23.4 | I37: 33251 | J37: 5.9 | K37: 55.9 | L37: 100 | M37: 47.4 | N37: 20.4 | O37: 137428.2 | P37: 82456.9 | Q37: 274856.3
A38: 37 | B38: 4 | C38: =_xlfn.XLOOKUP(company_perf[[#This Row],[company_id]],'company_info'!A:A,'company_info'!B:B) -> Company_4 | D38: =VLOOKUP(company_perf[[#This Row],[company_id]],company_info[],3,FALSE) -> Technology | E38: =VLOOKUP(company_perf[[#This Row],[company_id]],company_info[],4,FALSE) -> Africa | F38: 2018 | G38: 5978.5 | H38: 26.1 | I38: 31801 | J38: 8.8 | K38: 55.6 | L38: 99.7 | M38: 46.3 | N38: 20.7 | O38: 150000 | P38: 90000 | Q38: 300000
A39: 38 | B39: 4 | C39: =_xlfn.XLOOKUP(company_perf[[#This Row],[company_id]],'company_info'!A:A,'company_info'!B:B) -> Company_4 | D39: =VLOOKUP(company_perf[[#This Row],[company_id]],company_info[],3,FALSE) -> Technology | E39: =VLOOKUP(company_perf[[#This Row],[company_id]],company_info[],4,FALSE) -> Africa | F39: 2019 | G39: 6529.4 | H39: 28.2 | I39: 42706.4 | J39: 9.2 | K39: 56 | L39: 100 | M39: 46.1 | N39: 21.8 | O39: 163234.8 | P39: 97940.9 | Q39: 326469.6
A40: 39 | B40: 4 | C40: =_xlfn.XLOOKUP(company_perf[[#This Row],[company_id]],'company_info'!A:A,'company_info'!B:B) -> Company_4 | D40: =VLOOKUP(company_perf[[#This Row],[company_id]],company_info[],3,FALSE) -> Technology | E40: =VLOOKUP(company_perf[[#This Row],[company_id]],company_info[],4,FALSE) -> Africa | F40: 2020 | G40: 6123.5 | H40: 30.6 | I40: 38574.1 | J40: -6.2 | K40: 58.4 | L40: 100 | M40: 50.9 | N40: 24.4 | O40: 153087.8 | P40: 91852.7 | Q40: 306175.6
...
